<?xml version="1.0" encoding="utf-8"?>
<!-- This URDF was automatically created by SolidWorks to URDF Exporter! Originally created by Stephen Brawner (brawner@gmail.com) 
     Commit Version: 1.6.0-4-g7f85cfe  Build Version: 1.6.7995.38578
     For more information, please see http://wiki.ros.org/sw_urdf_exporter -->
<robot
  name="Final555Assembly">
  <link
    name="base_link">
    <inertial>
      <origin
        xyz="0.0771175017135775 -0.107771067421505 0.188664208736546"
        rpy="0 0 0" />
      <mass
        value="28.5330754639332" />
      <inertia
        ixx="0.326743067163912"
        ixy="0.00813670255648942"
        ixz="0.000910378205996769"
        iyy="12.1941702487415"
        iyz="-3.8730301390126E-06"
        izz="11.9799900289709" />
    </inertial>
    <visual>
      <origin
        xyz="0 0 0"
        rpy="0 0 0" />
      <geometry>
        <mesh
          filename="package://Final555Assembly/meshes/base_link.STL" />
      </geometry>
      <material
        name="">
        <color
          rgba="0.792156862745098 0.819607843137255 0.933333333333333 1" />
      </material>
    </visual>
    <collision>
      <origin
        xyz="0 0 0"
        rpy="0 0 0" />
      <geometry>
        <mesh
          filename="package://Final555Assembly/meshes/base_link.STL" />
      </geometry>
    </collision>
  </link>
  <link
    name="Link1">
    <inertial>
      <origin
        xyz="-2.3203E-09 -0.00031456 0.10979"
        rpy="0 0 0" />
      <mass
        value="0.032841" />
      <inertia
        ixx="0.00025619"
        ixy="-5.1172E-14"
        ixz="8.4008E-12"
        iyy="0.00025307"
        iyz="-2.9701E-07"
        izz="3.6661E-06" />
    </inertial>
    <visual>
      <origin
        xyz="0 0 0"
        rpy="0 0 0" />
      <geometry>
        <mesh
          filename="package://Final555Assembly/meshes/Link1.STL" />
      </geometry>
      <material
        name="">
        <color
          rgba="0.99608 0.99608 1 1" />
      </material>
    </visual>
    <collision>
      <origin
        xyz="0 0 0"
        rpy="0 0 0" />
      <geometry>
        <mesh
          filename="package://Final555Assembly/meshes/Link1.STL" />
      </geometry>
    </collision>
  </link>
  <joint
    name="joint3"
    type="revolute">
    <origin
      xyz="0.011359 -0.16261 0.29955"
      rpy="1.364 0 -1.9502" />
    <parent
      link="base_link" />
    <child
      link="Link1" />
    <axis
      xyz="0 1 0" />
    <limit
      lower="-0.7"
      upper="1.5"
      effort="0"
      velocity="0" />
    <mimic
      joint=""
      multiplier="1"
      offset="0" />
  </joint>
  <link
    name="Link2">
    <inertial>
      <origin
        xyz="-2.3203E-09 -0.00031456 0.10979"
        rpy="0 0 0" />
      <mass
        value="0.032841" />
      <inertia
        ixx="0.00025619"
        ixy="-5.1172E-14"
        ixz="8.4008E-12"
        iyy="0.00025307"
        iyz="-2.9701E-07"
        izz="3.6661E-06" />
    </inertial>
    <visual>
      <origin
        xyz="0 0 0"
        rpy="0 0 0" />
      <geometry>
        <mesh
          filename="package://Final555Assembly/meshes/Link2.STL" />
      </geometry>
      <material
        name="">
        <color
          rgba="0.99608 0.99608 1 1" />
      </material>
    </visual>
    <collision>
      <origin
        xyz="0 0 0"
        rpy="0 0 0" />
      <geometry>
        <mesh
          filename="package://Final555Assembly/meshes/Link2.STL" />
      </geometry>
    </collision>
  </link>
  <joint
    name="joint1"
    type="revolute">
    <origin
      xyz="0.1356 -0.14019 0.29955"
      rpy="1.364 0 2.2386" />
    <parent
      link="base_link" />
    <child
      link="Link2" />
    <axis
      xyz="0 1 0" />
    <limit
      lower="-0.7"
      upper="1.5"
      effort="0"
      velocity="0" />
  </joint>
  <link
    name="link3">
    <inertial>
      <origin
        xyz="0 0 0"
        rpy="0 0 0" />
      <mass
        value="0" />
      <inertia
        ixx="0"
        ixy="0"
        ixz="0"
        iyy="0"
        iyz="0"
        izz="0" />
    </inertial>
    <visual>
      <origin
        xyz="0 0 0"
        rpy="0 0 0" />
      <geometry>
        <mesh
          filename="package://Final555Assembly/meshes/link3.STL" />
      </geometry>
      <material
        name="">
        <color
          rgba="1 1 1 1" />
      </material>
    </visual>
    <collision>
      <origin
        xyz="0 0 0"
        rpy="0 0 0" />
      <geometry>
        <mesh
          filename="package://Final555Assembly/meshes/link3.STL" />
      </geometry>
    </collision>
  </link>
  <joint
    name="joint2"
    type="revolute">
    <origin
      xyz="0.092898 -0.259 0.29955"
      rpy="1.364 0 0.14424" />
    <parent
      link="base_link" />
    <child
      link="link3" />
    <axis
      xyz="0 1 0" />
    <limit
      lower="-0.7"
      upper="1.5"
      effort="0"
      velocity="0" />
  </joint>
</robot>